What is the try/catch Statement?
Overview
The try/catch statement is used to handle errors in JavaScript. It allows you to test a block of code for errors and specify what to do if an error occurs. This prevents the script from breaking and provides a way to handle exceptions gracefully245.


Syntax

The basic syntax of the try/catch statement is as follows:

try {
    // Block of code to try
} catch (err) {
    // Block of code to handle errors
} finally {
    // Block of code to be executed regardless of the result
}


The try Block
Description
The try block contains the code that you want to test for errors. If any statement within the try block (or in a function called from within the try block) throws an exception, control immediately shifts to the catch bloc

EXAMPLE : 

try {
    let x = y + 7; // This will throw an error because y is not defined
} catch (err) {
    console.log("An error occurred: " + err.message);
}


The catch Block
Description
The catch block specifies what to do if an exception is thrown in the try block. The catch block takes an identifier (err in the example above) that holds the value specified by the throw statement. This identifier is only available within the scope of the catch block


EXAMPLE : 

try {
    throw "Something went wrong";
} catch (err) {
    console.log("Caught an error: " + err);
}



Conditional Catch Blocks
You can create conditional catch blocks by combining try/catch with if/else if/else structures to handle different types of exceptions.


try {
    myRoutine(); // May throw different types of exceptions
} catch (e) {
    if (e instanceof TypeError) {
        console.log("Type error occurred");
    } else if (e instanceof RangeError) {
        console.log("Range error occurred");
    } else {
        console.log("Unknown error occurred");
    }
}



The finally Block
Description
The finally block contains code that will be executed regardless of whether an exception was thrown or not. It is optional but useful for cleaning up resources or performing other necessary actions after the try and catch blocks have been executed


try {
    console.log("Trying to execute some code");
} catch (err) {
    console.log("An error occurred: " + err.message);
} finally {
    console.log("This will always be executed");
}



Overwriting Return Values by the finally Block
The finally block can overwrite the return values or throw statements from the try and catch blocks.

  function f() {
    try {
        console.log(0);
        throw "bogus";
    } catch (e) {
        console.log(1);
        return true; // This return is suspended until the finally block completes
    } finally {
        console.log(3);
        return false; // Overwrites the previous return
    }
}

console.log(f()); // Output: 0, 1, 3, false




The throw Statement
Description
The throw statement is used to throw an exception. You can throw any expression, not just specific types. This allows you to create custom errors and control program flow15.

  
  Example :

throw "Error message"; // String type
throw 42; // Number type
throw true; // Boolean type
throw { toString() { return "I'm an object!"; } }; // Object type



Nested try Blocks
Description
You can nest try blocks, although it is generally advised against due to readability issues. Nesting allows you to use a single catch block for multiple try blocks or have separate catch blocks for each try block4


EXAMPLE : 

try {
    try {
        throw new Error("Inner error");
    } catch (ex) {
        console.error("Inner catch error", ex.message);
    } finally {
        console.log("Finally from inner try");
    }
} catch (ex) {
    console.error("Outer catch error", ex.message);
}





Practical Examples
Input Validation
Here is an example of using try/catch for input validation:


function myFunction() {
    let x = document.getElementById("demo").value;
    try {
        if (x == "") throw "is Empty";
        if (isNaN(x)) throw "not a number";
        if (x > 10) throw "too high";
        if (x < 5) throw "too low";
    } catch (err) {
        document.getElementById("message").innerHTML = "Input " + err;
    } finally {
        document.getElementById("demo").value = "";
    }
}




Custom Error Handling
You can use try/catch to handle custom errors and provide meaningful error messages.

function CustomError(message) {
    this.value = "customError";
    this.message = message;
}

try {
    throw new CustomError("Data is not defined");
} catch (e) {
    alert(e.message);
}



Conclusion
The try/catch statement is a powerful tool in JavaScript for handling errors and exceptions. By using try, catch, and optionally finally, you can ensure that your code remains robust and continues to execute even when errors occur. Here are the key points summarized:
try Block: Contains the code to be tested for errors.
catch Block: Specifies what to do if an exception is thrown in the try block.
finally Block: Executes code regardless of whether an exception was thrown or not.
throw Statement: Used to throw custom exceptions.
Nested try Blocks: Allows for nested error handling, though it can be complex and less readable.
Practical Examples: Useful in scenarios like input validation and custom error handling.
  

